<mujoco model="go2_description">
  <default>
    <default class="robot">
      <default class="motor">
        <joint axis="0 1 0" damping="2" armature="0.01"/>
        <general forcerange="-24 24" biastype="affine" gainprm="50 0 0" biasprm="0 -50 -0.5"/>
        <default class="abduction">
          <general ctrlrange="-0.9472 0.9472"/>
        </default>
        <default class="hip">
          <general ctrlrange="-1.4 2.5"/>
        </default>
        <default class="knee">
          <general ctrlrange="-2.6227 -0.84776"/>
        </default>
      </default>

      <default class="visual">
        <geom type="mesh" contype="0" conaffinity="0" group="2" />
      </default>
      <default class="collision">
        <geom material="transparent" condim="3" contype="0" conaffinity="1" priority="1" group="1" solref="0.005 1" solimp="0.99 0.999 1e-05" friction="1 0.01 0.01" />
        <default class="foot">
          <geom priority="1" solimp="0.015 1 0.031" condim="6"
            friction="0.8 0.02 0.01"/>
        </default>
      </default>
    </default>
  </default>

  <compiler angle="radian" autolimits="true"/>

  <asset>
    <material name="metal" rgba=".9 .95 .95 1"/>
    <material name="black" rgba="0 0 0 1"/>
    <material name="white" rgba="1 1 1 1"/>
    <material name="gray" rgba="0.671705 0.692426 0.774270 1"/>
    <material name="transparent" rgba="1 1 1 0"/>

    <mesh name="base_0" file="./assets/base_0.obj"/>
    <mesh name="base_1" file="./assets/base_1.obj"/>
    <mesh name="base_2" file="./assets/base_2.obj"/>
    <mesh name="base_3" file="./assets/base_3.obj"/>
    <mesh name="base_4" file="./assets/base_4.obj"/>
    <mesh name="hip_0" file="./assets/hip_0.obj"/>
    <mesh name="hip_1" file="./assets/hip_1.obj"/>
    <mesh name="thigh_0" file="./assets/thigh_0.obj"/>
    <mesh name="thigh_1" file="./assets/thigh_1.obj"/>
    <mesh name="thigh_mirror_0" file="./assets/thigh_mirror_0.obj"/>
    <mesh name="thigh_mirror_1" file="./assets/thigh_mirror_1.obj"/>
    <mesh name="calf_0" file="./assets/calf_0.obj"/>
    <mesh name="calf_1" file="./assets/calf_1.obj"/>
    <mesh name="calf_mirror_0" file="./assets/calf_mirror_0.obj"/>
    <mesh name="calf_mirror_1" file="./assets/calf_mirror_1.obj"/>
    <mesh name="foot" file="./assets/foot.obj"/>

    <mesh name="base_convex.stl" file="./collisions/base_convex.stl" />
    <mesh name="thigh_convex.stl" file="./collisions/thigh_convex.stl" />
    <mesh name="calf_upper_convex.stl" file="./collisions/calf_upper_convex.stl" />
    <mesh name="calf_lower_convex.stl" file="./collisions/calf_lower_convex.stl" />
    <mesh name="foot_convex.stl" file="./collisions/foot_convex.stl" />
    <mesh name="thigh_mirror_convex.stl" file="./collisions/thigh_mirror_convex.stl" />
    <mesh name="calf_upper_mirror_convex.stl" file="./collisions/calf_upper_mirror_convex.stl" />
    <mesh name="calf_lower_mirror_convex.stl" file="./collisions/calf_lower_mirror_convex.stl" />
    <mesh name="hip_convex.stl" file="./collisions/hip_convex.stl" />
  </asset>

  <worldbody>
    <body name="base" pos="0.00000000 0.00000000 0.42600000" quat="1 0 0 0" childclass="robot">
      <inertial pos="0.021112 0 -0.005366" quat="-0.000543471 0.713435 -0.00173769 0.700719" mass="6.921"
        diaginertia="0.107027 0.0980771 0.0244531"/>
      <freejoint name="floating_base" />
      <geom name="base_collision" pos="0 0 0" quat="1 0 0 0" type="mesh" mesh="base_convex.stl" class="collision" />
      <geom mesh="base_0" material="black" class="visual"/>
      <geom mesh="base_1" material="black" class="visual"/>
      <geom mesh="base_2" material="black" class="visual"/>
      <geom mesh="base_3" material="white" class="visual"/>
      <geom mesh="base_4" material="gray" class="visual"/>
      <body name="FL_hip" pos="0.1934 0.0465 0" quat="1.0 0.0 0.0 0.0">
        <joint name="FL_hip_joint" type="hinge" ref="0.0" class="motor" range="-1.0472 1.0472" axis="1 0 0" />
        <inertial pos="-0.0054 0.00194 -0.000105" quat="1.0 0.0 0.0 0.0" mass="0.678" diaginertia="0.00048 0.000884 0.000596" />
        <geom name="FL_hip_collision" pos="0 0 0" quat="1.0 0.0 0.0 0.0" type="mesh" mesh="hip_convex.stl" class="collision" />
        <geom mesh="hip_0" material="metal" class="visual"/>
        <geom mesh="hip_1" material="gray" class="visual"/>
        <body name="FL_thigh" pos="0 0.0955 0" quat="1.0 0.0 0.0 0.0">
          <joint name="FL_thigh_joint" type="hinge" ref="0.0" class="motor" range="-1.5708 3.4907" axis="0 1 0" />
          <inertial pos="-0.00374 -0.0223 -0.0327" quat="1.0 0.0 0.0 0.0" mass="1.152" diaginertia="0.00584 0.0058 0.00103" />
          <geom name="FL_thigh_collision" pos="0 0 0" quat="1 0 0 0" type="mesh" mesh="thigh_convex.stl" class="collision" />
          <geom mesh="thigh_0" material="metal" class="visual"/>
          <geom mesh="thigh_1" material="gray" class="visual"/>
          <body name="FL_calf" pos="0 0 -0.213" quat="1.0 0.0 0.0 0.0">
            <joint name="FL_calf_joint" type="hinge" ref="0.0" class="motor" range="-2.7227 -0.83776" axis="0 1 0" />
            <inertial pos="0.00548 -0.000975 -0.115" quat="1.0 0.0 0.0 0.0" mass="0.154" diaginertia="0.00108 0.0011 3.29e-05" />
            <geom name="FL_calf_collision_0" pos="0 0 0" quat="1 0 0 0" type="mesh" mesh="calf_upper_convex.stl" class="collision" />
            <geom name="FL_calf_collision_1" pos="0 0 0" quat="1 0 0 0" type="mesh" mesh="calf_lower_convex.stl" class="collision" />
            <geom mesh="calf_0" material="gray" class="visual"/>
            <geom mesh="calf_1" material="black" class="visual"/>
            <body name="FL_foot" pos="0 0 -0.213" quat="1.0 0.0 0.0 0.0">
              <inertial pos="0 0 0" quat="1.0 0.0 0.0 0.0" mass="0.04" diaginertia="9.6e-06 9.6e-06 9.6e-06" />
              <geom name="FL_foot_collision" pos="0 0 0" quat="1 0 0 0" type="mesh" mesh="foot_convex.stl" class="foot" />
              <geom mesh="foot" class="visual" material="black"/>
            </body>
          </body>
          <body name="FL_calf_rotor" pos="0 -0.03235 0" quat="1.0 0.0 0.0 0.0">
            <inertial pos="0.0 0.0 0.0" quat="1.0 0.0 0.0 0.0" mass="0.089" diaginertia="5.9647e-05 0.000111842 5.9647e-05" />
          </body>
        </body>
        <body name="FL_thigh_rotor" pos="0 -0.00015 0" quat="1.0 0.0 0.0 0.0">
          <inertial pos="0.0 0.0 0.0" quat="1.0 0.0 0.0 0.0" mass="0.089" diaginertia="5.9647e-05 0.000111842 5.9647e-05" />
        </body>
      </body>
      <body name="FL_hip_rotor" pos="0.11215 0.04675 0" quat="1.0 0.0 0.0 0.0">
        <inertial pos="0.0 0.0 0.0" quat="1.0 0.0 0.0 0.0" mass="0.089" diaginertia="0.000111842 5.9647e-05 5.9647e-05" />
      </body>
      <body name="FR_hip" pos="0.1934 -0.0465 0" quat="1.0 0.0 0.0 0.0">
        <joint name="FR_hip_joint" type="hinge" ref="0.0" class="motor" range="-1.0472 1.0472" axis="1 0 0" />
        <inertial pos="-0.0054 -0.00194 -0.000105" quat="1.0 0.0 0.0 0.0" mass="0.678" diaginertia="0.00048 0.000884 0.000596" />
        <geom name="FR_hip_collision" pos="0 0 0" quat="4.63268e-05 1 0 0" type="mesh" mesh="hip_convex.stl" class="collision" />
        <geom mesh="hip_0" material="metal" class="visual" quat="4.63268e-05 1 0 0"/>
        <geom mesh="hip_1" material="gray" class="visual" quat="4.63268e-05 1 0 0"/>
        <body name="FR_thigh" pos="0 -0.0955 0" quat="1.0 0.0 0.0 0.0">
          <joint name="FR_thigh_joint" type="hinge" ref="0.0" class="motor" range="-1.5708 3.4907" axis="0 1 0" />
          <inertial pos="-0.00374 0.0223 -0.0327" quat="1.0 0.0 0.0 0.0" mass="1.152" diaginertia="0.00584 0.0058 0.00103" />
          <geom name="FR_thigh_collision" pos="0 0 0" quat="1 0 0 0" type="mesh" mesh="thigh_mirror_convex.stl" class="collision" />
          <geom mesh="thigh_mirror_0" material="metal" class="visual"/>
          <geom mesh="thigh_mirror_1" material="gray" class="visual"/>
          <body name="FR_calf" pos="0 0 -0.213" quat="1.0 0.0 0.0 0.0">
            <joint name="FR_calf_joint" type="hinge" ref="0.0" class="motor" range="-2.7227 -0.83776" axis="0 1 0" />
            <inertial pos="0.00548 0.000975 -0.115" quat="1.0 0.0 0.0 0.0" mass="0.154" diaginertia="0.00108 0.0011 3.29e-05" />
            <geom name="FR_calf_collision_0" pos="0 0 0" quat="1 0 0 0" type="mesh" mesh="calf_upper_mirror_convex.stl" class="collision" />
            <geom name="FR_calf_collision_1" pos="0 0 0" quat="1 0 0 0" type="mesh" mesh="calf_lower_mirror_convex.stl" class="collision" />
            <geom mesh="calf_mirror_0" material="gray" class="visual"/>
            <geom mesh="calf_mirror_1" material="black" class="visual"/>
            <body name="FR_foot" pos="0 0 -0.213" quat="1.0 0.0 0.0 0.0">
              <inertial pos="0 0 0" quat="1.0 0.0 0.0 0.0" mass="0.04" diaginertia="9.6e-06 9.6e-06 9.6e-06" />
              <geom name="FR_foot_collision" pos="0 0 0" quat="1 0 0 0" type="mesh" mesh="foot_convex.stl" class="foot" />
              <geom mesh="foot" class="visual" material="black"/>
            </body>
          </body>
          <body name="FR_calf_rotor" pos="0 0.03235 0" quat="1.0 0.0 0.0 0.0">
            <inertial pos="0.0 0.0 0.0" quat="1.0 0.0 0.0 0.0" mass="0.089" diaginertia="5.9647e-05 0.000111842 5.9647e-05" />
          </body>
        </body>
        <body name="FR_thigh_rotor" pos="0 0.00015 0" quat="1.0 0.0 0.0 0.0">
          <inertial pos="0.0 0.0 0.0" quat="1.0 0.0 0.0 0.0" mass="0.089" diaginertia="5.9647e-05 0.000111842 5.9647e-05" />
        </body>
      </body>
      <body name="FR_hip_rotor" pos="0.11215 -0.04675 0" quat="1.0 0.0 0.0 0.0">
        <inertial pos="0.0 0.0 0.0" quat="1.0 0.0 0.0 0.0" mass="0.089" diaginertia="0.000111842 5.9647e-05 5.9647e-05" />
      </body>
      <body name="RL_hip" pos="-0.1934 0.0465 0" quat="1.0 0.0 0.0 0.0">
        <joint name="RL_hip_joint" type="hinge" ref="0.0" class="motor" range="-1.0472 1.0472" axis="1 0 0" />
        <inertial pos="0.0054 0.00194 -0.000105" quat="1.0 0.0 0.0 0.0" mass="0.678" diaginertia="0.00048 0.000884 0.000596" />
        <geom name="RL_hip_collision" pos="0 0 0" quat="4.632679487995776e-05 0.0 0.999999998926914 0.0" type="mesh" mesh="hip_convex.stl" class="collision" />
        <geom mesh="hip_0" material="metal" class="visual" quat="4.63268e-05 0 1 0"/>
        <geom mesh="hip_1" material="gray" class="visual" quat="4.63268e-05 0 1 0"/>
        <body name="RL_thigh" pos="0 0.0955 0" quat="1.0 0.0 0.0 0.0">
          <joint name="RL_thigh_joint" type="hinge" ref="0.0" class="motor" range="-0.5236 4.5379" axis="0 1 0" />
          <inertial pos="-0.00374 -0.0223 -0.0327" quat="1.0 0.0 0.0 0.0" mass="1.152" diaginertia="0.00584 0.0058 0.00103" />
          <geom name="RL_thigh_collision" pos="0 0 0" quat="1 0 0 0" type="mesh" mesh="thigh_convex.stl" class="collision" />
          <geom mesh="thigh_0" material="metal" class="visual"/>
          <geom mesh="thigh_1" material="gray" class="visual"/>
          <body name="RL_calf" pos="0 0 -0.213" quat="1.0 0.0 0.0 0.0">
            <joint name="RL_calf_joint" type="hinge" ref="0.0" class="motor" range="-2.7227 -0.83776" axis="0 1 0" />
            <inertial pos="0.00548 -0.000975 -0.115" quat="1.0 0.0 0.0 0.0" mass="0.154" diaginertia="0.00108 0.0011 3.29e-05" />
            <geom name="RL_calf_collision_0" pos="0 0 0" quat="1 0 0 0" type="mesh" mesh="calf_upper_convex.stl" class="collision" />
            <geom name="RL_calf_collision_1" pos="0 0 0" quat="1 0 0 0" type="mesh" mesh="calf_lower_convex.stl" class="collision" />
            <geom mesh="calf_0" material="gray" class="visual"/>
            <geom mesh="calf_1" material="black" class="visual"/>
            <body name="RL_foot" pos="0 0 -0.213" quat="1.0 0.0 0.0 0.0">
              <inertial pos="0 0 0" quat="1.0 0.0 0.0 0.0" mass="0.04" diaginertia="9.6e-06 9.6e-06 9.6e-06" />
              <geom name="RL_foot_collision" pos="0 0 0" quat="1 0 0 0" type="mesh" mesh="foot_convex.stl" class="foot" />
              <geom mesh="foot" class="visual" material="black"/>
            </body>
          </body>
          <body name="RL_calf_rotor" pos="0 -0.03235 0" quat="1.0 0.0 0.0 0.0">
            <inertial pos="0.0 0.0 0.0" quat="1.0 0.0 0.0 0.0" mass="0.089" diaginertia="5.9647e-05 0.000111842 5.9647e-05" />
          </body>
        </body>
        <body name="RL_thigh_rotor" pos="0 -0.00015 0" quat="1.0 0.0 0.0 0.0">
          <inertial pos="0.0 0.0 0.0" quat="1.0 0.0 0.0 0.0" mass="0.089" diaginertia="5.9647e-05 0.000111842 5.9647e-05" />
        </body>
      </body>
      <body name="RL_hip_rotor" pos="-0.11215 0.04675 0" quat="1.0 0.0 0.0 0.0">
        <inertial pos="0.0 0.0 0.0" quat="1.0 0.0 0.0 0.0" mass="0.089" diaginertia="0.000111842 5.9647e-05 5.9647e-05" />
      </body>
      <body name="RR_hip" pos="-0.1934 -0.0465 0" quat="1.0 0.0 0.0 0.0">
        <joint name="RR_hip_joint" type="hinge" ref="0.0" class="motor" range="-1.0472 1.0472" axis="1 0 0" />
        <inertial pos="0.0054 -0.00194 -0.000105" quat="1.0 0.0 0.0 0.0" mass="0.678" diaginertia="0.00048 0.000884 0.000596" />
        <geom name="RR_hip_collision" pos="0 0 0" quat="2.14617192384968e-09 4.632679483024512e-05 4.632679483024512e-05 -0.9999999978538281" type="mesh" mesh="hip_convex.stl" class="collision" />
        <geom mesh="hip_0" material="metal" class="visual" quat="2.14617e-09 4.63268e-05 4.63268e-05 -1"/>
        <geom mesh="hip_1" material="gray" class="visual" quat="2.14617e-09 4.63268e-05 4.63268e-05 -1"/>
        <body name="RR_thigh" pos="0 -0.0955 0" quat="1.0 0.0 0.0 0.0">
          <joint name="RR_thigh_joint" type="hinge" ref="0.0" class="motor" range="-0.5236 4.5379" axis="0 1 0" />
          <inertial pos="-0.00374 0.0223 -0.0327" quat="1.0 0.0 0.0 0.0" mass="1.152" diaginertia="0.00584 0.0058 0.00103" />
          <geom name="RR_thigh_collision" pos="0 0 0" quat="1 0 0 0" type="mesh" mesh="thigh_mirror_convex.stl" class="collision" />
          <geom mesh="thigh_mirror_0" material="metal" class="visual"/>
          <geom mesh="thigh_mirror_1" material="gray" class="visual"/>
          <body name="RR_calf" pos="0 0 -0.213" quat="1.0 0.0 0.0 0.0">
            <joint name="RR_calf_joint" type="hinge" ref="0.0" class="motor" range="-2.7227 -0.83776" axis="0 1 0" />
            <inertial pos="0.00548 0.000975 -0.115" quat="1.0 0.0 0.0 0.0" mass="0.154" diaginertia="0.00108 0.0011 3.29e-05" />
            <geom name="RR_calf_collision_0" pos="0 0 0" quat="1 0 0 0" type="mesh" mesh="calf_upper_mirror_convex.stl" class="collision" />
            <geom name="RR_calf_collision_1" pos="0 0 0" quat="1 0 0 0" type="mesh" mesh="calf_lower_mirror_convex.stl" class="collision" />
            <geom mesh="calf_mirror_0" material="gray" class="visual"/>
            <geom mesh="calf_mirror_1" material="black" class="visual"/>
            <body name="RR_foot" pos="0 0 -0.213" quat="1.0 0.0 0.0 0.0">
              <inertial pos="0 0 0" quat="1.0 0.0 0.0 0.0" mass="0.04" diaginertia="9.6e-06 9.6e-06 9.6e-06" />
              <geom name="RR_foot_collision" pos="0 0 0" quat="1 0 0 0" type="mesh" mesh="foot_convex.stl" class="foot" />
              <geom mesh="foot" class="visual" material="black"/>
            </body>
          </body>
          <body name="RR_calf_rotor" pos="0 0.03235 0" quat="1.0 0.0 0.0 0.0">
            <inertial pos="0.0 0.0 0.0" quat="1.0 0.0 0.0 0.0" mass="0.089" diaginertia="5.9647e-05 0.000111842 5.9647e-05" />
          </body>
        </body>
        <body name="RR_thigh_rotor" pos="0 0.00015 0" quat="1.0 0.0 0.0 0.0">
          <inertial pos="0.0 0.0 0.0" quat="1.0 0.0 0.0 0.0" mass="0.089" diaginertia="5.9647e-05 0.000111842 5.9647e-05" />
        </body>
      </body>
      <body name="RR_hip_rotor" pos="-0.11215 -0.04675 0" quat="1.0 0.0 0.0 0.0">
        <inertial pos="0.0 0.0 0.0" quat="1.0 0.0 0.0 0.0" mass="0.089" diaginertia="0.000111842 5.9647e-05 5.9647e-05" />
      </body>

      <site name="radar" pos="0.28945 0 -0.046825" quat="0.1313159683094573 0.0 0.9913405653290647 0.0" />
      <site name="imu" pos="-0.02557 0 0.04232" />
      <camera name="front_camera" mode="track" fovy="90.0" quat="4.329780281177467e-17 4.329780281177466e-17 0.7071067811865475 0.7071067811865476" pos="0.0 2.0 0.5" />
      <camera name="side_camera" mode="track" fovy="90.0" quat="-0.5 -0.4999999999999999 0.5 0.5000000000000001" pos="-2.0 0.0 0.5" />
    </body>
  </worldbody>

  <actuator>
    <general class="abduction" name="FL_hip" joint="FL_hip_joint"/>
    <general class="hip" name="FL_thigh" joint="FL_thigh_joint"/>
    <general class="knee" name="FL_calf" joint="FL_calf_joint"/>
    <general class="abduction" name="FR_hip" joint="FR_hip_joint"/>
    <general class="hip" name="FR_thigh" joint="FR_thigh_joint"/>
    <general class="knee" name="FR_calf" joint="FR_calf_joint"/>
    <general class="abduction" name="RL_hip" joint="RL_hip_joint"/>
    <general class="hip" name="RL_thigh" joint="RL_thigh_joint"/>
    <general class="knee" name="RL_calf" joint="RL_calf_joint"/>
    <general class="abduction" name="RR_hip" joint="RR_hip_joint"/>
    <general class="hip" name="RR_thigh" joint="RR_thigh_joint"/>
    <general class="knee" name="RR_calf" joint="RR_calf_joint"/>
  </actuator>

  <contact>
    <exclude body1="FL_thigh" body2="FL_calf" />
    <exclude body1="FL_calf" body2="FL_foot" />
    <exclude body1="FR_thigh" body2="FR_calf" />
    <exclude body1="FR_calf" body2="FR_foot" />
    <exclude body1="base" body2="RL_hip" />
    <exclude body1="RL_hip" body2="RL_thigh" />
    <exclude body1="RL_thigh" body2="RL_calf" />
    <exclude body1="RL_calf" body2="RL_foot" />
    <exclude body1="base" body2="RR_hip" />
    <exclude body1="RR_hip" body2="RR_thigh" />
    <exclude body1="RR_thigh" body2="RR_calf" />
    <exclude body1="RR_calf" body2="RR_foot" />
  </contact>

  <sensor>
    <jointpos joint="FL_hip_joint" name="abduction_front_left_pos"/>
    <jointpos joint="FL_thigh_joint" name="hip_front_left_pos"/>
    <jointpos joint="FL_calf_joint" name="knee_front_left_pos"/>
    <jointpos joint="RL_hip_joint" name="abduction_hind_left_pos"/>
    <jointpos joint="RL_thigh_joint" name="hip_hind_left_pos"/>
    <jointpos joint="RL_calf_joint" name="knee_hind_left_pos"/>
    <jointpos joint="FR_hip_joint" name="abduction_front_right_pos"/>
    <jointpos joint="FR_thigh_joint" name="hip_front_right_pos"/>
    <jointpos joint="FR_calf_joint" name="knee_front_right_pos"/>
    <jointpos joint="RR_hip_joint" name="abduction_hind_right_pos"/>
    <jointpos joint="RR_thigh_joint" name="hip_hind_right_pos"/>
    <jointpos joint="RR_calf_joint" name="knee_hind_right_pos"/>
    <jointvel joint="FL_hip_joint" name="abduction_front_left_vel"/>
    <jointvel joint="FL_thigh_joint" name="hip_front_left_vel"/>
    <jointvel joint="FL_calf_joint" name="knee_front_left_vel"/>
    <jointvel joint="RL_hip_joint" name="abduction_hind_left_vel"/>
    <jointvel joint="RL_thigh_joint" name="hip_hind_left_vel"/>
    <jointvel joint="RL_calf_joint" name="knee_hind_left_vel"/>
    <jointvel joint="FR_hip_joint" name="abduction_front_right_vel"/>
    <jointvel joint="FR_thigh_joint" name="hip_front_right_vel"/>
    <jointvel joint="FR_calf_joint" name="knee_front_right_vel"/>
    <jointvel joint="RR_hip_joint" name="abduction_hind_right_vel"/>
    <jointvel joint="RR_thigh_joint" name="hip_hind_right_vel"/>
    <jointvel joint="RR_calf_joint" name="knee_hind_right_vel"/>
    <gyro site="imu" name="gyro"/>
    <accelerometer site="imu" name="accelerometer"/>
    <framequat objtype="site" objname="imu" name="orientation"/>
    <framepos objtype="site" objname="imu" name="global_position"/>
    <framelinvel objtype="site" objname="imu" name="global_linvel"/>
    <frameangvel objtype="site" objname="imu" name="global_angvel"/>
  </sensor>

  <keyframe>
    <key name="home" qpos="0 0 0.27 1 0 0 0 0 0.9 -1.8 0 0.9 -1.8 0 0.9 -1.8 0 0.9 -1.8"
      ctrl="0 0.9 -1.8 0 0.9 -1.8 0 0.9 -1.8 0 0.9 -1.8"/>
  </keyframe>
</mujoco>